<?xml version="1.0" encoding="utf-8"?>
<!-- =================================================================================== -->
<!-- |    This document was autogenerated by xacro from oped.urdf.xacro                | -->
<!-- |    EDITING THIS FILE BY HAND IS NOT RECOMMENDED                                 | -->
<!-- =================================================================================== -->
<robot name="oped">
  <material name="black">
    <color rgba="0.15 0.15 0.15 1.0"/>
  </material>
  <link name="base_link">
    <collision>
      <origin rpy="0 0 0" xyz="0 0 0"/>
      <geometry>
        <mesh filename="package://oped_description/meshes/base_x.dae"/>
      </geometry>
    </collision>
    <visual>
      <origin rpy="0 0 0" xyz="0 0 0"/>
      <geometry>
        <mesh filename="package://oped_description/meshes/base_x.dae"/>
      </geometry>
      <material name="black"/>
    </visual>
  </link>
  <link name="base_inertia">
    <inertial>
      <origin xyz="0 0 0"/>
      <mass value="0.7"/>
      <inertia ixx="0.00252956666667" ixy="0.0" ixz="0.0" iyy="0.00301373333333" iyz="0.0" izz="0.000876633333333"/>
    </inertial>
  </link>
  <joint name="base_link_to_base_inertia" type="fixed">
    <parent link="base_link"/>
    <child link="base_inertia"/>
    <origin rpy="0 0 0" xyz="0 0 0"/>
  </joint>
  <gazebo reference="base_link">
    <material>Gazebo/FlatBlack</material>
  </gazebo>
  <!-- Init colour -->
  <material name="dark">
    <color rgba="0.3 0.3 0.3 1.0"/>
  </material>
  <material name="light_black">
    <color rgba="0.4 0.4 0.4 1.0"/>
  </material>
  <material name="blue">
    <color rgba="0.0 0.0 0.8 1.0"/>
  </material>
  <material name="green">
    <color rgba="0.0 0.8 0.0 1.0"/>
  </material>
  <material name="grey">
    <color rgba="0.5 0.5 0.5 1.0"/>
  </material>
  <material name="orange">
    <color rgba="1.0 0.423529411765 0.0392156862745 1.0"/>
  </material>
  <material name="brown">
    <color rgba="0.870588235294 0.811764705882 0.764705882353 1.0"/>
  </material>
  <material name="red">
    <color rgba="0.8 0.0 0.0 1.0"/>
  </material>
  <material name="white">
    <color rgba="1.0 1.0 1.0 1.0"/>
  </material>
  <gazebo reference="lidar_frame">
    <material>Gazebo/FlatBlack</material>
    <sensor name="lds_lfcd_sensor" type="ray">
      <pose>0 0 0 0 0 0</pose>
      <visualize>false</visualize>
      <update_rate>5</update_rate>
      <ray>
        <scan>
          <horizontal>
            <samples>360</samples>
            <resolution>1</resolution>
            <min_angle>0.0</min_angle>
            <max_angle>6.28319</max_angle>
          </horizontal>
        </scan>
        <range>
          <min>0.120</min>
          <max>10.0</max>
          <resolution>0.5</resolution>
        </range>
        <noise>
          <type>gaussian</type>
          <mean>0.0</mean>
          <stddev>0.01</stddev>
        </noise>
      </ray>
      <plugin filename="libgazebo_ros_laser.so" name="gazebo_ros_lds_lfcd_controller">
        <topicName>scan</topicName>
        <frameName>lidar_frame</frameName>
      </plugin>
    </sensor>
  </gazebo>
  <joint name="scan_joint" type="fixed">
    <parent link="base_link"/>
    <child link="lidar_frame"/>
    <origin rpy="0 0 0" xyz="-0.007 0 0.077"/>
  </joint>
  <link name="lidar_frame">
    <visual>
      <origin rpy="0 0 0" xyz="0.007 0 -0.067"/>
      <geometry>
        <mesh filename="package://oped_description/meshes/rplidar.dae"/>
      </geometry>
    </visual>
    <collision>
      <origin rpy="0 0 0" xyz="0 0 0.01"/>
      <geometry>
        <cylinder length="0.0315" radius="0.035"/>
      </geometry>
      <material name="dark"/>
    </collision>
    <inertial>
      <mass value="0.001"/>
      <origin xyz="0 0 0"/>
      <inertia ixx="0.000001" ixy="0.0" ixz="0.0" iyy="0.000001" iyz="0.0" izz="0.000001"/>
    </inertial>
  </link>
  <gazebo>
    <plugin filename="libhector_gazebo_ros_imu.so" name="imu_controller">
      <robotNamespace>/</robotNamespace>
      <updateRate>50.0</updateRate>
      <bodyName>imu_link</bodyName>
      <topicName>imu/data</topicName>
      <accelDrift>0.005 0.005 0.005</accelDrift>
      <accelGaussianNoise>0.005 0.005 0.005</accelGaussianNoise>
      <rateDrift>0.005 0.005 0.005 </rateDrift>
      <rateGaussianNoise>0.005 0.005 0.005 </rateGaussianNoise>
      <headingDrift>0.005</headingDrift>
      <headingGaussianNoise>0.005</headingGaussianNoise>
    </plugin>
  </gazebo>
  <link name="imu_link">
    <inertial>
      <mass value="0.001"/>
      <origin rpy="0 0 0" xyz="0 0 0"/>
      <inertia ixx="1e-09" ixy="0.0" ixz="0.0" iyy="1e-09" iyz="0.0" izz="1e-09"/>
    </inertial>
  </link>
  <joint name="imu_joint" type="fixed">
    <parent link="base_link"/>
    <child link="imu_link"/>
  </joint>
  <link name="lf_hip_debug_link"/>
  <link name="lf_hip_link">
    <inertial>
      <mass value="0.05"/>
      <inertia ixx="1.69770833333e-05" ixy="0.0" ixz="0.0" iyy="1.24052083333e-05" iyz="0.0" izz="9.78020833333e-06"/>
    </inertial>
    <collision>
      <origin rpy="0 0 -3.14159" xyz="0 0 0"/>
      <geometry>
        <mesh filename="package://oped_description/meshes/hip.dae"/>
      </geometry>
    </collision>
    <visual>
      <origin rpy="0 0 -3.14159" xyz="0 0 0"/>
      <geometry>
        <mesh filename="package://oped_description/meshes/hip.dae"/>
      </geometry>
      <material name="black"/>
    </visual>
  </link>
  <gazebo reference="lf_hip_link">
    <material>Gazebo/FlatBlack</material>
  </gazebo>
  <link name="lf_upper_leg_link">
    <inertial>
      <origin xyz="0 0 -0.03225"/>
      <mass value="0.025"/>
      <inertia ixx="1.98258541667e-05" ixy="0.0" ixz="0.0" iyy="8.90085416667e-06" iyz="0.0" izz="2.13416666667e-05"/>
    </inertial>
    <collision>
      <origin rpy="0 0 0" xyz="0 0 0"/>
      <geometry>
        <mesh filename="package://oped_description/meshes/left_upper_leg.dae"/>
      </geometry>
    </collision>
    <visual>
      <origin rpy="0 0 0" xyz="0 0 0"/>
      <geometry>
        <mesh filename="package://oped_description/meshes/left_upper_leg.dae"/>
      </geometry>
      <material name="black"/>
    </visual>
  </link>
  <gazebo reference="lf_upper_leg_link">
    <material>Gazebo/FlatBlack</material>
  </gazebo>
  <link name="lf_lower_leg_link">
    <inertial>
      <origin xyz="0 0 -0.09285"/>
      <mass value="0.025"/>
      <inertia ixx="5.65146977721e-06" ixy="0.0" ixz="0.0" iyy="8.12310416667e-06" iyz="0.0" izz="3.23253227721e-06"/>
    </inertial>
    <collision>
      <origin rpy="0 0 0" xyz="0 0 0"/>
      <geometry>
        <mesh filename="package://oped_description/meshes/lower_leg.dae"/>
      </geometry>
    </collision>
    <visual>
      <origin rpy="0 0 0" xyz="0 0 0"/>
      <geometry>
        <mesh filename="package://oped_description/meshes/lower_leg.dae"/>
      </geometry>
      <material name="black"/>
    </visual>
  </link>
  <gazebo reference="lf_lower_leg_link">
    <kp>1000000.0</kp>
    <kd>1.0</kd>
    <mu1>0.8</mu1>
    <mu2>0.8</mu2>
    <maxVel>0.0</maxVel>
    <minDepth>0.001</minDepth>
    <material>Gazebo/FlatBlack</material>
  </gazebo>
  <link name="lf_foot_link"/>
  <joint name="lf_debug_joint" type="fixed">
    <parent link="base_link"/>
    <child link="lf_hip_debug_link"/>
    <origin rpy="0 0 0" xyz="0.099 0.04177 0"/>
  </joint>
  <joint name="lf_hip_joint" type="revolute">
    <axis xyz="1 0 0"/>
    <limit effort="1000" lower="-3.14159265359" upper="3.14159265359" velocity="1.5"/>
    <!-- <limit effort="25" lower="-0.68" upper="0.68" velocity="1.5" /> -->
    <parent link="base_link"/>
    <child link="lf_hip_link"/>
    <origin rpy="0 0 0" xyz="0.099 0.04177 0"/>
  </joint>
  <joint name="lf_upper_leg_joint" type="revolute">
    <axis xyz="0 1 0"/>
    <limit effort="1000" lower="-3.14159265359" upper="3.14159265359" velocity="1.5"/>
    <parent link="lf_hip_link"/>
    <child link="lf_upper_leg_link"/>
    <origin rpy="0 0 0" xyz="0 0.052 0"/>
  </joint>
  <joint name="lf_lower_leg_joint" type="revolute">
    <axis xyz="0 1 0"/>
    <limit effort="1000" lower="-3.14159265359" upper="3.14159265359" velocity="1.5"/>
    <!-- <limit effort="25" lower="-2.84" upper="0.54" velocity="1.5" /> -->
    <parent link="lf_upper_leg_link"/>
    <child link="lf_lower_leg_link"/>
    <origin rpy="0 0 0" xyz="0 0.0015 -0.0645"/>
  </joint>
  <joint name="lf_foot_joint" type="fixed">
    <parent link="lf_lower_leg_link"/>
    <child link="lf_foot_link"/>
    <origin rpy="0 0 0" xyz="0 0 -0.118"/>
  </joint>
  <transmission name="lf_hip_joint_trans">
    <type>transmission_interface/SimpleTransmission</type>
    <joint name="lf_hip_joint">
      <hardwareInterface>hardware_interface/EffortJointInterface</hardwareInterface>
    </joint>
    <actuator name="lf_hip_joint_motor">
      <hardwareInterface>hardware_interface/EffortJointInterface</hardwareInterface>
      <mechanicalReduction>1</mechanicalReduction>
    </actuator>
  </transmission>
  <transmission name="lf_upper_leg_joint_trans">
    <type>transmission_interface/SimpleTransmission</type>
    <joint name="lf_upper_leg_joint">
      <hardwareInterface>hardware_interface/EffortJointInterface</hardwareInterface>
    </joint>
    <actuator name="lf_upper_leg_joint_motor">
      <hardwareInterface>hardware_interface/EffortJointInterface</hardwareInterface>
      <mechanicalReduction>1</mechanicalReduction>
    </actuator>
  </transmission>
  <transmission name="lf_lower_leg_joint_trans">
    <type>transmission_interface/SimpleTransmission</type>
    <joint name="lf_lower_leg_joint">
      <hardwareInterface>hardware_interface/EffortJointInterface</hardwareInterface>
    </joint>
    <actuator name="lf_lower_joint_motor">
      <hardwareInterface>hardware_interface/EffortJointInterface</hardwareInterface>
      <mechanicalReduction>1</mechanicalReduction>
    </actuator>
  </transmission>
  <link name="lh_hip_debug_link"/>
  <link name="lh_hip_link">
    <inertial>
      <mass value="0.05"/>
      <inertia ixx="1.69770833333e-05" ixy="0.0" ixz="0.0" iyy="1.24052083333e-05" iyz="0.0" izz="9.78020833333e-06"/>
    </inertial>
    <collision>
      <origin rpy="0 0 -3.14159" xyz="0 0 0"/>
      <geometry>
        <mesh filename="package://oped_description/meshes/hip.dae"/>
      </geometry>
    </collision>
    <visual>
      <origin rpy="0 0 -3.14159" xyz="0 0 0"/>
      <geometry>
        <mesh filename="package://oped_description/meshes/hip.dae"/>
      </geometry>
      <material name="black"/>
    </visual>
  </link>
  <gazebo reference="lh_hip_link">
    <material>Gazebo/FlatBlack</material>
  </gazebo>
  <link name="lh_upper_leg_link">
    <inertial>
      <origin xyz="0 0 -0.03225"/>
      <mass value="0.025"/>
      <inertia ixx="1.98258541667e-05" ixy="0.0" ixz="0.0" iyy="8.90085416667e-06" iyz="0.0" izz="2.13416666667e-05"/>
    </inertial>
    <collision>
      <origin rpy="0 0 -3.14159" xyz="0 0 0"/>
      <geometry>
        <mesh filename="package://oped_description/meshes/left_upper_leg.dae"/>
      </geometry>
    </collision>
    <visual>
      <origin rpy="0 0 -3.14159" xyz="0 0 0"/>
      <geometry>
        <mesh filename="package://oped_description/meshes/left_upper_leg.dae"/>
      </geometry>
      <material name="black"/>
    </visual>
  </link>
  <gazebo reference="lh_upper_leg_link">
    <material>Gazebo/FlatBlack</material>
  </gazebo>
  <link name="lh_lower_leg_link">
    <inertial>
      <origin xyz="0 0 -0.09285"/>
      <mass value="0.025"/>
      <inertia ixx="5.65146977721e-06" ixy="0.0" ixz="0.0" iyy="8.12310416667e-06" iyz="0.0" izz="3.23253227721e-06"/>
    </inertial>
    <collision>
      <origin rpy="0 0 -3.14159" xyz="0 0 0"/>
      <geometry>
        <mesh filename="package://oped_description/meshes/lower_leg.dae"/>
      </geometry>
    </collision>
    <visual>
      <origin rpy="0 0 -3.14159" xyz="0 0 0"/>
      <geometry>
        <mesh filename="package://oped_description/meshes/lower_leg.dae"/>
      </geometry>
      <material name="black"/>
    </visual>
  </link>
  <gazebo reference="lh_lower_leg_link">
    <kp>1000000.0</kp>
    <kd>1.0</kd>
    <mu1>0.8</mu1>
    <mu2>0.8</mu2>
    <maxVel>0.0</maxVel>
    <minDepth>0.001</minDepth>
    <material>Gazebo/FlatBlack</material>
  </gazebo>
  <link name="lh_foot_link"/>
  <joint name="lh_debug_joint" type="fixed">
    <parent link="base_link"/>
    <child link="lh_hip_debug_link"/>
    <origin rpy="0 0 0" xyz="-0.095 0.04177 0"/>
  </joint>
  <joint name="lh_hip_joint" type="revolute">
    <axis xyz="1 0 0"/>
    <limit effort="1000" lower="-3.14159265359" upper="3.14159265359" velocity="1.5"/>
    <!-- <limit effort="25" lower="-0.68" upper="0.68" velocity="1.5" /> -->
    <parent link="base_link"/>
    <child link="lh_hip_link"/>
    <origin rpy="0 0 0" xyz="-0.095 0.04177 0"/>
  </joint>
  <joint name="lh_upper_leg_joint" type="revolute">
    <axis xyz="0 1 0"/>
    <limit effort="1000" lower="-3.14159265359" upper="3.14159265359" velocity="1.5"/>
    <parent link="lh_hip_link"/>
    <child link="lh_upper_leg_link"/>
    <origin rpy="0 0 0" xyz="0 0.052 0"/>
  </joint>
  <joint name="lh_lower_leg_joint" type="revolute">
    <axis xyz="0 1 0"/>
    <limit effort="1000" lower="-3.14159265359" upper="3.14159265359" velocity="1.5"/>
    <!-- <limit effort="25" lower="-2.84" upper="0.54" velocity="1.5" /> -->
    <parent link="lh_upper_leg_link"/>
    <child link="lh_lower_leg_link"/>
    <origin rpy="0 0 0" xyz="0 0.0015 -0.0645"/>
  </joint>
  <joint name="lh_foot_joint" type="fixed">
    <parent link="lh_lower_leg_link"/>
    <child link="lh_foot_link"/>
    <origin rpy="0 0 0" xyz="0 0 -0.118"/>
  </joint>
  <transmission name="lh_hip_joint_trans">
    <type>transmission_interface/SimpleTransmission</type>
    <joint name="lh_hip_joint">
      <hardwareInterface>hardware_interface/EffortJointInterface</hardwareInterface>
    </joint>
    <actuator name="lh_hip_joint_motor">
      <hardwareInterface>hardware_interface/EffortJointInterface</hardwareInterface>
      <mechanicalReduction>1</mechanicalReduction>
    </actuator>
  </transmission>
  <transmission name="lh_upper_leg_joint_trans">
    <type>transmission_interface/SimpleTransmission</type>
    <joint name="lh_upper_leg_joint">
      <hardwareInterface>hardware_interface/EffortJointInterface</hardwareInterface>
    </joint>
    <actuator name="lh_upper_leg_joint_motor">
      <hardwareInterface>hardware_interface/EffortJointInterface</hardwareInterface>
      <mechanicalReduction>1</mechanicalReduction>
    </actuator>
  </transmission>
  <transmission name="lh_lower_leg_joint_trans">
    <type>transmission_interface/SimpleTransmission</type>
    <joint name="lh_lower_leg_joint">
      <hardwareInterface>hardware_interface/EffortJointInterface</hardwareInterface>
    </joint>
    <actuator name="lh_lower_joint_motor">
      <hardwareInterface>hardware_interface/EffortJointInterface</hardwareInterface>
      <mechanicalReduction>1</mechanicalReduction>
    </actuator>
  </transmission>
  <link name="rf_hip_debug_link"/>
  <link name="rf_hip_link">
    <inertial>
      <mass value="0.05"/>
      <inertia ixx="1.69770833333e-05" ixy="0.0" ixz="0.0" iyy="1.24052083333e-05" iyz="0.0" izz="9.78020833333e-06"/>
    </inertial>
    <collision>
      <origin rpy="0 0 0" xyz="0 0 0"/>
      <geometry>
        <mesh filename="package://oped_description/meshes/hip.dae"/>
      </geometry>
    </collision>
    <visual>
      <origin rpy="0 0 0" xyz="0 0 0"/>
      <geometry>
        <mesh filename="package://oped_description/meshes/hip.dae"/>
      </geometry>
      <material name="black"/>
    </visual>
  </link>
  <gazebo reference="rf_hip_link">
    <material>Gazebo/FlatBlack</material>
  </gazebo>
  <link name="rf_upper_leg_link">
    <inertial>
      <origin xyz="0 0 -0.03225"/>
      <mass value="0.025"/>
      <inertia ixx="1.98258541667e-05" ixy="0.0" ixz="0.0" iyy="8.90085416667e-06" iyz="0.0" izz="2.13416666667e-05"/>
    </inertial>
    <collision>
      <origin rpy="0 0 0" xyz="0 0 0"/>
      <geometry>
        <mesh filename="package://oped_description/meshes/right_upper_leg.dae"/>
      </geometry>
    </collision>
    <visual>
      <origin rpy="0 0 0" xyz="0 0 0"/>
      <geometry>
        <mesh filename="package://oped_description/meshes/right_upper_leg.dae"/>
      </geometry>
      <material name="black"/>
    </visual>
  </link>
  <gazebo reference="rf_upper_leg_link">
    <material>Gazebo/FlatBlack</material>
  </gazebo>
  <link name="rf_lower_leg_link">
    <inertial>
      <origin xyz="0 0 -0.09285"/>
      <mass value="0.025"/>
      <inertia ixx="5.65146977721e-06" ixy="0.0" ixz="0.0" iyy="8.12310416667e-06" iyz="0.0" izz="3.23253227721e-06"/>
    </inertial>
    <collision>
      <origin rpy="0 0 0" xyz="0 0 0"/>
      <geometry>
        <mesh filename="package://oped_description/meshes/lower_leg.dae"/>
      </geometry>
    </collision>
    <visual>
      <origin rpy="0 0 0" xyz="0 0 0"/>
      <geometry>
        <mesh filename="package://oped_description/meshes/lower_leg.dae"/>
      </geometry>
      <material name="black"/>
    </visual>
  </link>
  <gazebo reference="rf_lower_leg_link">
    <kp>1000000.0</kp>
    <kd>1.0</kd>
    <mu1>0.8</mu1>
    <mu2>0.8</mu2>
    <maxVel>0.0</maxVel>
    <minDepth>0.001</minDepth>
    <material>Gazebo/FlatBlack</material>
  </gazebo>
  <link name="rf_foot_link"/>
  <joint name="rf_debug_joint" type="fixed">
    <parent link="base_link"/>
    <child link="rf_hip_debug_link"/>
    <origin rpy="0 0 0" xyz="0.099 -0.04177 0"/>
  </joint>
  <joint name="rf_hip_joint" type="revolute">
    <axis xyz="1 0 0"/>
    <limit effort="1000" lower="-3.14159265359" upper="3.14159265359" velocity="1.5"/>
    <!-- <limit effort="25" lower="-0.68" upper="0.68" velocity="1.5" /> -->
    <parent link="base_link"/>
    <child link="rf_hip_link"/>
    <origin rpy="0 0 0" xyz="0.099 -0.04177 0"/>
  </joint>
  <joint name="rf_upper_leg_joint" type="revolute">
    <axis xyz="0 1 0"/>
    <limit effort="1000" lower="-3.14159265359" upper="3.14159265359" velocity="1.5"/>
    <parent link="rf_hip_link"/>
    <child link="rf_upper_leg_link"/>
    <origin rpy="0 0 0" xyz="0 -0.052 0"/>
  </joint>
  <joint name="rf_lower_leg_joint" type="revolute">
    <axis xyz="0 1 0"/>
    <limit effort="1000" lower="-3.14159265359" upper="3.14159265359" velocity="1.5"/>
    <!-- <limit effort="25" lower="-2.84" upper="0.54" velocity="1.5" /> -->
    <parent link="rf_upper_leg_link"/>
    <child link="rf_lower_leg_link"/>
    <origin rpy="0 0 0" xyz="0 -0.002 -0.0645"/>
  </joint>
  <joint name="rf_foot_joint" type="fixed">
    <parent link="rf_lower_leg_link"/>
    <child link="rf_foot_link"/>
    <origin rpy="0 0 0" xyz="0 0 -0.118"/>
  </joint>
  <transmission name="rf_hip_joint_trans">
    <type>transmission_interface/SimpleTransmission</type>
    <joint name="rf_hip_joint">
      <hardwareInterface>hardware_interface/EffortJointInterface</hardwareInterface>
    </joint>
    <actuator name="rf_hip_joint_motor">
      <hardwareInterface>hardware_interface/EffortJointInterface</hardwareInterface>
      <mechanicalReduction>1</mechanicalReduction>
    </actuator>
  </transmission>
  <transmission name="rf_upper_leg_joint_trans">
    <type>transmission_interface/SimpleTransmission</type>
    <joint name="rf_upper_leg_joint">
      <hardwareInterface>hardware_interface/EffortJointInterface</hardwareInterface>
    </joint>
    <actuator name="rf_upper_leg_joint_motor">
      <hardwareInterface>hardware_interface/EffortJointInterface</hardwareInterface>
      <mechanicalReduction>1</mechanicalReduction>
    </actuator>
  </transmission>
  <transmission name="rf_lower_leg_joint_trans">
    <type>transmission_interface/SimpleTransmission</type>
    <joint name="rf_lower_leg_joint">
      <hardwareInterface>hardware_interface/EffortJointInterface</hardwareInterface>
    </joint>
    <actuator name="rf_lower_joint_motor">
      <hardwareInterface>hardware_interface/EffortJointInterface</hardwareInterface>
      <mechanicalReduction>1</mechanicalReduction>
    </actuator>
  </transmission>
  <link name="rh_hip_debug_link"/>
  <link name="rh_hip_link">
    <inertial>
      <mass value="0.05"/>
      <inertia ixx="1.69770833333e-05" ixy="0.0" ixz="0.0" iyy="1.24052083333e-05" iyz="0.0" izz="9.78020833333e-06"/>
    </inertial>
    <collision>
      <origin rpy="0 0 0" xyz="0 0 0"/>
      <geometry>
        <mesh filename="package://oped_description/meshes/hip.dae"/>
      </geometry>
    </collision>
    <visual>
      <origin rpy="0 0 0" xyz="0 0 0"/>
      <geometry>
        <mesh filename="package://oped_description/meshes/hip.dae"/>
      </geometry>
      <material name="black"/>
    </visual>
  </link>
  <gazebo reference="rh_hip_link">
    <material>Gazebo/FlatBlack</material>
  </gazebo>
  <link name="rh_upper_leg_link">
    <inertial>
      <origin xyz="0 0 -0.03225"/>
      <mass value="0.025"/>
      <inertia ixx="1.98258541667e-05" ixy="0.0" ixz="0.0" iyy="8.90085416667e-06" iyz="0.0" izz="2.13416666667e-05"/>
    </inertial>
    <collision>
      <origin rpy="0 0 -3.14159" xyz="0 0 0"/>
      <geometry>
        <mesh filename="package://oped_description/meshes/right_upper_leg.dae"/>
      </geometry>
    </collision>
    <visual>
      <origin rpy="0 0 -3.14159" xyz="0 0 0"/>
      <geometry>
        <mesh filename="package://oped_description/meshes/right_upper_leg.dae"/>
      </geometry>
      <material name="black"/>
    </visual>
  </link>
  <gazebo reference="rh_upper_leg_link">
    <material>Gazebo/FlatBlack</material>
  </gazebo>
  <link name="rh_lower_leg_link">
    <inertial>
      <origin xyz="0 0 -0.09285"/>
      <mass value="0.025"/>
      <inertia ixx="5.65146977721e-06" ixy="0.0" ixz="0.0" iyy="8.12310416667e-06" iyz="0.0" izz="3.23253227721e-06"/>
    </inertial>
    <collision>
      <origin rpy="0 0 -3.14159" xyz="0 0 0"/>
      <geometry>
        <mesh filename="package://oped_description/meshes/lower_leg.dae"/>
      </geometry>
    </collision>
    <visual>
      <origin rpy="0 0 -3.14159" xyz="0 0 0"/>
      <geometry>
        <mesh filename="package://oped_description/meshes/lower_leg.dae"/>
      </geometry>
      <material name="black"/>
    </visual>
  </link>
  <gazebo reference="rh_lower_leg_link">
    <kp>1000000.0</kp>
    <kd>1.0</kd>
    <mu1>0.8</mu1>
    <mu2>0.8</mu2>
    <maxVel>0.0</maxVel>
    <minDepth>0.001</minDepth>
    <material>Gazebo/FlatBlack</material>
  </gazebo>
  <link name="rh_foot_link"/>
  <joint name="rh_debug_joint" type="fixed">
    <parent link="base_link"/>
    <child link="rh_hip_debug_link"/>
    <origin rpy="0 0 0" xyz="-0.095 -0.04177 0"/>
  </joint>
  <joint name="rh_hip_joint" type="revolute">
    <axis xyz="1 0 0"/>
    <limit effort="1000" lower="-3.14159265359" upper="3.14159265359" velocity="1.5"/>
    <!-- <limit effort="25" lower="-0.68" upper="0.68" velocity="1.5" /> -->
    <parent link="base_link"/>
    <child link="rh_hip_link"/>
    <origin rpy="0 0 0" xyz="-0.095 -0.04177 0"/>
  </joint>
  <joint name="rh_upper_leg_joint" type="revolute">
    <axis xyz="0 1 0"/>
    <limit effort="1000" lower="-3.14159265359" upper="3.14159265359" velocity="1.5"/>
    <parent link="rh_hip_link"/>
    <child link="rh_upper_leg_link"/>
    <origin rpy="0 0 0" xyz="0 -0.052 0"/>
  </joint>
  <joint name="rh_lower_leg_joint" type="revolute">
    <axis xyz="0 1 0"/>
    <limit effort="1000" lower="-3.14159265359" upper="3.14159265359" velocity="1.5"/>
    <!-- <limit effort="25" lower="-2.84" upper="0.54" velocity="1.5" /> -->
    <parent link="rh_upper_leg_link"/>
    <child link="rh_lower_leg_link"/>
    <origin rpy="0 0 0" xyz="0 -0.002 -0.0645"/>
  </joint>
  <joint name="rh_foot_joint" type="fixed">
    <parent link="rh_lower_leg_link"/>
    <child link="rh_foot_link"/>
    <origin rpy="0 0 0" xyz="0 0 -0.118"/>
  </joint>
  <transmission name="rh_hip_joint_trans">
    <type>transmission_interface/SimpleTransmission</type>
    <joint name="rh_hip_joint">
      <hardwareInterface>hardware_interface/EffortJointInterface</hardwareInterface>
    </joint>
    <actuator name="rh_hip_joint_motor">
      <hardwareInterface>hardware_interface/EffortJointInterface</hardwareInterface>
      <mechanicalReduction>1</mechanicalReduction>
    </actuator>
  </transmission>
  <transmission name="rh_upper_leg_joint_trans">
    <type>transmission_interface/SimpleTransmission</type>
    <joint name="rh_upper_leg_joint">
      <hardwareInterface>hardware_interface/EffortJointInterface</hardwareInterface>
    </joint>
    <actuator name="rh_upper_leg_joint_motor">
      <hardwareInterface>hardware_interface/EffortJointInterface</hardwareInterface>
      <mechanicalReduction>1</mechanicalReduction>
    </actuator>
  </transmission>
  <transmission name="rh_lower_leg_joint_trans">
    <type>transmission_interface/SimpleTransmission</type>
    <joint name="rh_lower_leg_joint">
      <hardwareInterface>hardware_interface/EffortJointInterface</hardwareInterface>
    </joint>
    <actuator name="rh_lower_joint_motor">
      <hardwareInterface>hardware_interface/EffortJointInterface</hardwareInterface>
      <mechanicalReduction>1</mechanicalReduction>
    </actuator>
  </transmission>
  <gazebo>
    <plugin filename="libgazebo_ros_p3d.so" name="p3d_base_controller">
      <alwaysOn>true</alwaysOn>
      <updateRate>10.0</updateRate>
      <bodyName>base_link</bodyName>
      <topicName>odom/ground_truth</topicName>
      <gaussianNoise>0.01</gaussianNoise>
      <frameName>world</frameName>
      <xyzOffsets>0 0 0</xyzOffsets>
      <rpyOffsets>0 0 0</rpyOffsets>
    </plugin>
  </gazebo>
  <gazebo>
    <plugin filename="libgazebo_ros_control.so" name="gazebo_ros_control">
      <legacyModeNS>true</legacyModeNS>
    </plugin>
  </gazebo>
</robot>

